2024-09-25 12:03:19,887 INFO    StreamThr :91254 [internal.py:wandb_internal():86] W&B internal server running at pid: 91254, started at: 2024-09-25 12:03:19.887005
2024-09-25 12:03:19,888 DEBUG   HandlerThread:91254 [handler.py:handle_request():146] handle_request: status
2024-09-25 12:03:19,894 INFO    WriterThread:91254 [datastore.py:open_for_write():87] open: /Users/emresefer/Desktop/FinanceLab proje/Technical Indicator/wandb/run-20240925_120319-zfb077dz/run-zfb077dz.wandb
2024-09-25 12:03:19,894 DEBUG   SenderThread:91254 [sender.py:send():379] send: header
2024-09-25 12:03:19,919 DEBUG   SenderThread:91254 [sender.py:send():379] send: run
2024-09-25 12:03:20,338 ERROR   SenderThread:91254 [internal_api.py:execute():373] 404 response executing GraphQL.
2024-09-25 12:03:20,338 ERROR   SenderThread:91254 [internal_api.py:execute():374] {"errors":[{"message":"project not found","path":["upsertBucket"]}],"data":{"upsertBucket":null}}
2024-09-25 12:03:20,339 ERROR   SenderThread:91254 [sender.py:send_run():971] It appears that you do not have permission to access the requested resource. Please reach out to the project owner to grant you access. If you have the correct permissions, verify that there are no issues with your networking setup.(Error 404: Not Found)
Traceback (most recent call last):
  File "/opt/anaconda3/lib/python3.11/site-packages/wandb/sdk/lib/retry.py", line 131, in __call__
    result = self._call_fn(*args, **kwargs)
             ^^^^^^^^^^^^^^^^^^^^^^^^^^^^^^
  File "/opt/anaconda3/lib/python3.11/site-packages/wandb/sdk/internal/internal_api.py", line 369, in execute
    return self.client.execute(*args, **kwargs)  # type: ignore
           ^^^^^^^^^^^^^^^^^^^^^^^^^^^^^^^^^^^^
  File "/opt/anaconda3/lib/python3.11/site-packages/wandb/vendor/gql-0.2.0/wandb_gql/client.py", line 52, in execute
    result = self._get_result(document, *args, **kwargs)
             ^^^^^^^^^^^^^^^^^^^^^^^^^^^^^^^^^^^^^^^^^^^
  File "/opt/anaconda3/lib/python3.11/site-packages/wandb/vendor/gql-0.2.0/wandb_gql/client.py", line 60, in _get_result
    return self.transport.execute(document, *args, **kwargs)
           ^^^^^^^^^^^^^^^^^^^^^^^^^^^^^^^^^^^^^^^^^^^^^^^^^
  File "/opt/anaconda3/lib/python3.11/site-packages/wandb/sdk/lib/gql_request.py", line 59, in execute
    request.raise_for_status()
  File "/opt/anaconda3/lib/python3.11/site-packages/requests/models.py", line 1021, in raise_for_status
    raise HTTPError(http_error_msg, response=self)
requests.exceptions.HTTPError: 404 Client Error: Not Found for url: https://api.wandb.ai/graphql

During handling of the above exception, another exception occurred:

Traceback (most recent call last):
  File "/opt/anaconda3/lib/python3.11/site-packages/wandb/sdk/internal/sender.py", line 969, in send_run
    server_run = self._init_run(run, config_value_dict)
                 ^^^^^^^^^^^^^^^^^^^^^^^^^^^^^^^^^^^^^^
  File "/opt/anaconda3/lib/python3.11/site-packages/wandb/sdk/internal/sender.py", line 1014, in _init_run
    server_run, inserted, server_messages = self._api.upsert_run(
                                            ^^^^^^^^^^^^^^^^^^^^^
  File "/opt/anaconda3/lib/python3.11/site-packages/wandb/apis/normalize.py", line 73, in wrapper
    raise err
  File "/opt/anaconda3/lib/python3.11/site-packages/wandb/apis/normalize.py", line 41, in wrapper
    return func(*args, **kwargs)
           ^^^^^^^^^^^^^^^^^^^^^
  File "/opt/anaconda3/lib/python3.11/site-packages/wandb/sdk/internal/internal_api.py", line 2217, in upsert_run
    response = self.gql(
               ^^^^^^^^^
  File "/opt/anaconda3/lib/python3.11/site-packages/wandb/sdk/internal/internal_api.py", line 341, in gql
    ret = self._retry_gql(
          ^^^^^^^^^^^^^^^^
  File "/opt/anaconda3/lib/python3.11/site-packages/wandb/sdk/lib/retry.py", line 147, in __call__
    retry_timedelta_triggered = check_retry_fn(e)
                                ^^^^^^^^^^^^^^^^^
  File "/opt/anaconda3/lib/python3.11/site-packages/wandb/util.py", line 968, in check_retry_fn
    return fallback_retry_fn(e)
           ^^^^^^^^^^^^^^^^^^^^
  File "/opt/anaconda3/lib/python3.11/site-packages/wandb/util.py", line 910, in no_retry_auth
    raise CommError(
wandb.errors.CommError: It appears that you do not have permission to access the requested resource. Please reach out to the project owner to grant you access. If you have the correct permissions, verify that there are no issues with your networking setup.(Error 404: Not Found)
2024-09-25 12:03:20,637 DEBUG   HandlerThread:91254 [handler.py:handle_request():146] handle_request: shutdown
2024-09-25 12:03:20,637 INFO    HandlerThread:91254 [handler.py:finish():866] shutting down handler
2024-09-25 12:03:20,924 INFO    WriterThread:91254 [datastore.py:close():296] close: /Users/emresefer/Desktop/FinanceLab proje/Technical Indicator/wandb/run-20240925_120319-zfb077dz/run-zfb077dz.wandb
2024-09-25 12:03:21,351 INFO    SenderThread:91254 [sender.py:finish():1546] shutting down sender
